Workbook

Sheet Сравнение
A1: Сделка | B1: Категория | C1: Город | D1: ЦИАН | E1: Яндекс | F1: Авито | G1: Домклик | H1: Лидер
A2: Продажа | B2: Квартиры — всего | C2: 🇷🇺 Вся Россия | D2: =SUMIFS(ЦИАН!$D:$D,ЦИАН!$A:$A,"Продажи квартир",ЦИАН!$B:$B,"Квартиры в новостройках",ЦИАН!$C:$C,$C2)+SUMIFS(ЦИАН!$D:$D,ЦИАН!$A:$A,"Продажи квартир",ЦИАН!$B:$B,"Квартиры во вторичке",ЦИАН!$C:$C,$C2) | E2: =SUMIFS(Яндекс!$D:$D,Яндекс!$A:$A,"Купить",Яндекс!$B:$B,"Квартира в новостройке",Яндекс!$C:$C,$C2)+SUMIFS(Яндекс!$D:$D,Яндекс!$A:$A,"Купить",Яндекс!$B:$B,"Квартира во вторичке",Яндекс!$C:$C,$C2) | F2: =SUMIFS(Авито!$E:$E,Авито!$A:$A,"Продажа",Авито!$B:$B,"Квартиры",Авито!$C:$C,$C2) | G2: =SUMIFS(Домклик!$D:$D,Домклик!$A:$A,"Покупка",Домклик!$B:$B,"Квартиры",Домклик!$C:$C,$C2) | H2: =IFERROR(INDEX($D$1:$G$1,MATCH(MAX(D2:G2),D2:G2,0)),"")
A3: Продажа | B3: Квартиры — всего | C3: Москва | D3: =SUMIFS(ЦИАН!$D:$D,ЦИАН!$A:$A,"Продажи квартир",ЦИАН!$B:$B,"Квартиры в новостройках",ЦИАН!$C:$C,$C3)+SUMIFS(ЦИАН!$D:$D,ЦИАН!$A:$A,"Продажи квартир",ЦИАН!$B:$B,"Квартиры во вторичке",ЦИАН!$C:$C,$C3) | E3: =SUMIFS(Яндекс!$D:$D,Яндекс!$A:$A,"Купить",Яндекс!$B:$B,"Квартира в новостройке",Яндекс!$C:$C,$C3)+SUMIFS(Яндекс!$D:$D,Яндекс!$A:$A,"Купить",Яндекс!$B:$B,"Квартира во вторичке",Яндекс!$C:$C,$C3) | F3: =SUMIFS(Авито!$E:$E,Авито!$A:$A,"Продажа",Авито!$B:$B,"Квартиры",Авито!$C:$C,$C3) | G3: =SUMIFS(Домклик!$D:$D,Домклик!$A:$A,"Покупка",Домклик!$B:$B,"Квартиры",Домклик!$C:$C,$C3) | H3: =IFERROR(INDEX($D$1:$G$1,MATCH(MAX(D3:G3),D3:G3,0)),"")
A4: Продажа | B4: Квартиры — всего | C4: Санкт-Петербург | D4: =SUMIFS(ЦИАН!$D:$D,ЦИАН!$A:$A,"Продажи квартир",ЦИАН!$B:$B,"Квартиры в новостройках",ЦИАН!$C:$C,$C4)+SUMIFS(ЦИАН!$D:$D,ЦИАН!$A:$A,"Продажи квартир",ЦИАН!$B:$B,"Квартиры во вторичке",ЦИАН!$C:$C,$C4) | E4: =SUMIFS(Яндекс!$D:$D,Яндекс!$A:$A,"Купить",Яндекс!$B:$B,"Квартира в новостройке",Яндекс!$C:$C,$C4)+SUMIFS(Яндекс!$D:$D,Яндекс!$A:$A,"Купить",Яндекс!$B:$B,"Квартира во вторичке",Яндекс!$C:$C,$C4) | F4: =SUMIFS(Авито!$E:$E,Авито!$A:$A,"Продажа",Авито!$B:$B,"Квартиры",Авито!$C:$C,$C4) | G4: =SUMIFS(Домклик!$D:$D,Домклик!$A:$A,"Покупка",Домклик!$B:$B,"Квартиры",Домклик!$C:$C,$C4) | H4: =IFERROR(INDEX($D$1:$G$1,MATCH(MAX(D4:G4),D4:G4,0)),"")
A5: Продажа | B5: Квартиры — всего | C5: Новосибирск | D5: =SUMIFS(ЦИАН!$D:$D,ЦИАН!$A:$A,"Продажи квартир",ЦИАН!$B:$B,"Квартиры в новостройках",ЦИАН!$C:$C,$C5)+SUMIFS(ЦИАН!$D:$D,ЦИАН!$A:$A,"Продажи квартир",ЦИАН!$B:$B,"Квартиры во вторичке",ЦИАН!$C:$C,$C5) | E5: =SUMIFS(Яндекс!$D:$D,Яндекс!$A:$A,"Купить",Яндекс!$B:$B,"Квартира в новостройке",Яндекс!$C:$C,$C5)+SUMIFS(Яндекс!$D:$D,Яндекс!$A:$A,"Купить",Яндекс!$B:$B,"Квартира во вторичке",Яндекс!$C:$C,$C5) | F5: =SUMIFS(Авито!$E:$E,Авито!$A:$A,"Продажа",Авито!$B:$B,"Квартиры",Авито!$C:$C,$C5) | G5: =SUMIFS(Домклик!$D:$D,Домклик!$A:$A,"Покупка",Домклик!$B:$B,"Квартиры",Домклик!$C:$C,$C5) | H5: =IFERROR(INDEX($D$1:$G$1,MATCH(MAX(D5:G5),D5:G5,0)),"")
A6: Продажа | B6: Квартиры — всего | C6: Екатеринбург | D6: =SUMIFS(ЦИАН!$D:$D,ЦИАН!$A:$A,"Продажи квартир",ЦИАН!$B:$B,"Квартиры в новостройках",ЦИАН!$C:$C,$C6)+SUMIFS(ЦИАН!$D:$D,ЦИАН!$A:$A,"Продажи квартир",ЦИАН!$B:$B,"Квартиры во вторичке",ЦИАН!$C:$C,$C6) | E6: =SUMIFS(Яндекс!$D:$D,Яндекс!$A:$A,"Купить",Яндекс!$B:$B,"Квартира в новостройке",Яндекс!$C:$C,$C6)+SUMIFS(Яндекс!$D:$D,Яндекс!$A:$A,"Купить",Яндекс!$B:$B,"Квартира во вторичке",Яндекс!$C:$C,$C6) | F6: =SUMIFS(Авито!$E:$E,Авито!$A:$A,"Продажа",Авито!$B:$B,"Квартиры",Авито!$C:$C,$C6) | G6: =SUMIFS(Домклик!$D:$D,Домклик!$A:$A,"Покупка",Домклик!$B:$B,"Квартиры",Домклик!$C:$C,$C6) | H6: =IFERROR(INDEX($D$1:$G$1,MATCH(MAX(D6:G6),D6:G6,0)),"")
A7: Продажа | B7: Квартиры — всего | C7: Казань | D7: =SUMIFS(ЦИАН!$D:$D,ЦИАН!$A:$A,"Продажи квартир",ЦИАН!$B:$B,"Квартиры в новостройках",ЦИАН!$C:$C,$C7)+SUMIFS(ЦИАН!$D:$D,ЦИАН!$A:$A,"Продажи квартир",ЦИАН!$B:$B,"Квартиры во вторичке",ЦИАН!$C:$C,$C7) | E7: =SUMIFS(Яндекс!$D:$D,Яндекс!$A:$A,"Купить",Яндекс!$B:$B,"Квартира в новостройке",Яндекс!$C:$C,$C7)+SUMIFS(Яндекс!$D:$D,Яндекс!$A:$A,"Купить",Яндекс!$B:$B,"Квартира во вторичке",Яндекс!$C:$C,$C7) | F7: =SUMIFS(Авито!$E:$E,Авито!$A:$A,"Продажа",Авито!$B:$B,"Квартиры",Авито!$C:$C,$C7) | G7: =SUMIFS(Домклик!$D:$D,Домклик!$A:$A,"Покупка",Домклик!$B:$B,"Квартиры",Домклик!$C:$C,$C7) | H7: =IFERROR(INDEX($D$1:$G$1,MATCH(MAX(D7:G7),D7:G7,0)),"")
A8: Продажа | B8: Квартиры — всего | C8: Красноярск | D8: =SUMIFS(ЦИАН!$D:$D,ЦИАН!$A:$A,"Продажи квартир",ЦИАН!$B:$B,"Квартиры в новостройках",ЦИАН!$C:$C,$C8)+SUMIFS(ЦИАН!$D:$D,ЦИАН!$A:$A,"Продажи квартир",ЦИАН!$B:$B,"Квартиры во вторичке",ЦИАН!$C:$C,$C8) | E8: =SUMIFS(Яндекс!$D:$D,Яндекс!$A:$A,"Купить",Яндекс!$B:$B,"Квартира в новостройке",Яндекс!$C:$C,$C8)+SUMIFS(Яндекс!$D:$D,Яндекс!$A:$A,"Купить",Яндекс!$B:$B,"Квартира во вторичке",Яндекс!$C:$C,$C8) | F8: =SUMIFS(Авито!$E:$E,Авито!$A:$A,"Продажа",Авито!$B:$B,"Квартиры",Авито!$C:$C,$C8) | G8: =SUMIFS(Домклик!$D:$D,Домклик!$A:$A,"Покупка",Домклик!$B:$B,"Квартиры",Домклик!$C:$C,$C8) | H8: =IFERROR(INDEX($D$1:$G$1,MATCH(MAX(D8:G8),D8:G8,0)),"")
A9: Продажа | B9: Квартиры — всего | C9: Нижний Новгород | D9: =SUMIFS(ЦИАН!$D:$D,ЦИАН!$A:$A,"Продажи квартир",ЦИАН!$B:$B,"Квартиры в новостройках",ЦИАН!$C:$C,$C9)+SUMIFS(ЦИАН!$D:$D,ЦИАН!$A:$A,"Продажи квартир",ЦИАН!$B:$B,"Квартиры во вторичке",ЦИАН!$C:$C,$C9) | E9: =SUMIFS(Яндекс!$D:$D,Яндекс!$A:$A,"Купить",Яндекс!$B:$B,"Квартира в новостройке",Яндекс!$C:$C,$C9)+SUMIFS(Яндекс!$D:$D,Яндекс!$A:$A,"Купить",Яндекс!$B:$B,"Квартира во вторичке",Яндекс!$C:$C,$C9) | F9: =SUMIFS(Авито!$E:$E,Авито!$A:$A,"Продажа",Авито!$B:$B,"Квартиры",Авито!$C:$C,$C9) | G9: =SUMIFS(Домклик!$D:$D,Домклик!$A:$A,"Покупка",Домклик!$B:$B,"Квартиры",Домклик!$C:$C,$C9) | H9: =IFERROR(INDEX($D$1:$G$1,MATCH(MAX(D9:G9),D9:G9,0)),"")
A10: Продажа | B10: Квартиры — всего | C10: Челябинск | D10: =SUMIFS(ЦИАН!$D:$D,ЦИАН!$A:$A,"Продажи квартир",ЦИАН!$B:$B,"Квартиры в новостройках",ЦИАН!$C:$C,$C10)+SUMIFS(ЦИАН!$D:$D,ЦИАН!$A:$A,"Продажи квартир",ЦИАН!$B:$B,"Квартиры во вторичке",ЦИАН!$C:$C,$C10) | E10: =SUMIFS(Яндекс!$D:$D,Яндекс!$A:$A,"Купить",Яндекс!$B:$B,"Квартира в новостройке",Яндекс!$C:$C,$C10)+SUMIFS(Яндекс!$D:$D,Яндекс!$A:$A,"Купить",Яндекс!$B:$B,"Квартира во вторичке",Яндекс!$C:$C,$C10) | F10: =SUMIFS(Авито!$E:$E,Авито!$A:$A,"Продажа",Авито!$B:$B,"Квартиры",Авито!$C:$C,$C10) | G10: =SUMIFS(Домклик!$D:$D,Домклик!$A:$A,"Покупка",Домклик!$B:$B,"Квартиры",Домклик!$C:$C,$C10) | H10: =IFERROR(INDEX($D$1:$G$1,MATCH(MAX(D10:G10),D10:G10,0)),"")
A11: Продажа | B11: Квартиры — всего | C11: Уфа | D11: =SUMIFS(ЦИАН!$D:$D,ЦИАН!$A:$A,"Продажи квартир",ЦИАН!$B:$B,"Квартиры в новостройках",ЦИАН!$C:$C,$C11)+SUMIFS(ЦИАН!$D:$D,ЦИАН!$A:$A,"Продажи квартир",ЦИАН!$B:$B,"Квартиры во вторичке",ЦИАН!$C:$C,$C11) | E11: =SUMIFS(Яндекс!$D:$D,Яндекс!$A:$A,"Купить",Яндекс!$B:$B,"Квартира в новостройке",Яндекс!$C:$C,$C11)+SUMIFS(Яндекс!$D:$D,Яндекс!$A:$A,"Купить",Яндекс!$B:$B,"Квартира во вторичке",Яндекс!$C:$C,$C11) | F11: =SUMIFS(Авито!$E:$E,Авито!$A:$A,"Продажа",Авито!$B:$B,"Квартиры",Авито!$C:$C,$C11) | G11: =SUMIFS(Домклик!$D:$D,Домклик!$A:$A,"Покупка",Домклик!$B:$B,"Квартиры",Домклик!$C:$C,$C11) | H11: =IFERROR(INDEX($D$1:$G$1,MATCH(MAX(D11:G11),D11:G11,0)),"")
A12: Продажа | B12: Квартиры — всего | C12: Краснодар | D12: =SUMIFS(ЦИАН!$D:$D,ЦИАН!$A:$A,"Продажи квартир",ЦИАН!$B:$B,"Квартиры в новостройках",ЦИАН!$C:$C,$C12)+SUMIFS(ЦИАН!$D:$D,ЦИАН!$A:$A,"Продажи квартир",ЦИАН!$B:$B,"Квартиры во вторичке",ЦИАН!$C:$C,$C12) | E12: =SUMIFS(Яндекс!$D:$D,Яндекс!$A:$A,"Купить",Яндекс!$B:$B,"Квартира в новостройке",Яндекс!$C:$C,$C12)+SUMIFS(Яндекс!$D:$D,Яндекс!$A:$A,"Купить",Яндекс!$B:$B,"Квартира во вторичке",Яндекс!$C:$C,$C12) | F12: =SUMIFS(Авито!$E:$E,Авито!$A:$A,"Продажа",Авито!$B:$B,"Квартиры",Авито!$C:$C,$C12) | G12: =SUMIFS(Домклик!$D:$D,Домклик!$A:$A,"Покупка",Домклик!$B:$B,"Квартиры",Домклик!$C:$C,$C12) | H12: =IFERROR(INDEX($D$1:$G$1,MATCH(MAX(D12:G12),D12:G12,0)),"")
A13: Продажа | B13: Квартиры — всего | C13: Самара | D13: =SUMIFS(ЦИАН!$D:$D,ЦИАН!$A:$A,"Продажи квартир",ЦИАН!$B:$B,"Квартиры в новостройках",ЦИАН!$C:$C,$C13)+SUMIFS(ЦИАН!$D:$D,ЦИАН!$A:$A,"Продажи квартир",ЦИАН!$B:$B,"Квартиры во вторичке",ЦИАН!$C:$C,$C13) | E13: =SUMIFS(Яндекс!$D:$D,Яндекс!$A:$A,"Купить",Яндекс!$B:$B,"Квартира в новостройке",Яндекс!$C:$C,$C13)+SUMIFS(Яндекс!$D:$D,Яндекс!$A:$A,"Купить",Яндекс!$B:$B,"Квартира во вторичке",Яндекс!$C:$C,$C13) | F13: =SUMIFS(Авито!$E:$E,Авито!$A:$A,"Продажа",Авито!$B:$B,"Квартиры",Авито!$C:$C,$C13) | G13: =SUMIFS(Домклик!$D:$D,Домклик!$A:$A,"Покупка",Домклик!$B:$B,"Квартиры",Домклик!$C:$C,$C13) | H13: =IFERROR(INDEX($D$1:$G$1,MATCH(MAX(D13:G13),D13:G13,0)),"")
... A18: Продажа | B18: Квартиры — всего | C18: Волгоград | D18: =SUMIFS(ЦИАН!$D:$D,ЦИАН!$A:$A,"Продажи квартир",ЦИАН!$B:$B,"Квартиры в новостройках",ЦИАН!$C:$C,$C18)+SUMIFS(ЦИАН!$D:$D,ЦИАН!$A:$A,"Продажи квартир",ЦИАН!$B:$B,"Квартиры во вторичке",ЦИАН!$C:$C,$C18) | E18: =SUMIFS(Яндекс!$D:$D,Яндекс!$A:$A,"Купить",Яндекс!$B:$B,"Квартира в новостройке",Яндекс!$C:$C,$C18)+SUMIFS(Яндекс!$D:$D,Яндекс!$A:$A,"Купить",Яндекс!$B:$B,"Квартира во вторичке",Яндекс!$C:$C,$C18) | F18: =SUMIFS(Авито!$E:$E,Авито!$A:$A,"Продажа",Авито!$B:$B,"Квартиры",Авито!$C:$C,$C18) | G18: =SUMIFS(Домклик!$D:$D,Домклик!$A:$A,"Покупка",Домклик!$B:$B,"Квартиры",Домклик!$C:$C,$C18) | H18: =IFERROR(INDEX($D$1:$G$1,MATCH(MAX(D18:G18),D18:G18,0)),"")
A19: Продажа | B19: Квартиры — новостройки | C19: 🇷🇺 Вся Россия | D19: =SUMIFS(ЦИАН!$D:$D,ЦИАН!$A:$A,"Продажи квартир",ЦИАН!$B:$B,"Квартиры в новостройках",ЦИАН!$C:$C,$C19) | E19: =SUMIFS(Яндекс!$D:$D,Яндекс!$A:$A,"Купить",Яндекс!$B:$B,"Квартира в новостройке",Яндекс!$C:$C,$C19) | F19: =SUMIFS(Авито!$E:$E,Авито!$A:$A,"Продажа",Авито!$B:$B,"Квартиры новостройка",Авито!$C:$C,$C19) | G19: =SUMIFS(Домклик!$D:$D,Домклик!$A:$A,"Покупка",Домклик!$B:$B,"Квартиры новостройки",Домклик!$C:$C,$C19) | H19: =IFERROR(INDEX($D$1:$G$1,MATCH(MAX(D19:G19),D19:G19,0)),"")
A20: Продажа | B20: Квартиры — новостройки | C20: Москва | D20: =SUMIFS(ЦИАН!$D:$D,ЦИАН!$A:$A,"Продажи квартир",ЦИАН!$B:$B,"Квартиры в новостройках",ЦИАН!$C:$C,$C20) | E20: =SUMIFS(Яндекс!$D:$D,Яндекс!$A:$A,"Купить",Яндекс!$B:$B,"Квартира в новостройке",Яндекс!$C:$C,$C20) | F20: =SUMIFS(Авито!$E:$E,Авито!$A:$A,"Продажа",Авито!$B:$B,"Квартиры новостройка",Авито!$C:$C,$C20) | G20: =SUMIFS(Домклик!$D:$D,Домклик!$A:$A,"Покупка",Домклик!$B:$B,"Квартиры новостройки",Домклик!$C:$C,$C20) | H20: =IFERROR(INDEX($D$1:$G$1,MATCH(MAX(D20:G20),D20:G20,0)),"")
A21: Продажа | B21: Квартиры — новостройки | C21: Санкт-Петербург | D21: =SUMIFS(ЦИАН!$D:$D,ЦИАН!$A:$A,"Продажи квартир",ЦИАН!$B:$B,"Квартиры в новостройках",ЦИАН!$C:$C,$C21) | E21: =SUMIFS(Яндекс!$D:$D,Яндекс!$A:$A,"Купить",Яндекс!$B:$B,"Квартира в новостройке",Яндекс!$C:$C,$C21) | F21: =SUMIFS(Авито!$E:$E,Авито!$A:$A,"Продажа",Авито!$B:$B,"Квартиры новостройка",Авито!$C:$C,$C21) | G21: =SUMIFS(Домклик!$D:$D,Домклик!$A:$A,"Покупка",Домклик!$B:$B,"Квартиры новостройки",Домклик!$C:$C,$C21) | H21: =IFERROR(INDEX($D$1:$G$1,MATCH(MAX(D21:G21),D21:G21,0)),"")
A22: Продажа | B22: Квартиры — новостройки | C22: Новосибирск | D22: =SUMIFS(ЦИАН!$D:$D,ЦИАН!$A:$A,"Продажи квартир",ЦИАН!$B:$B,"Квартиры в новостройках",ЦИАН!$C:$C,$C22) | E22: =SUMIFS(Яндекс!$D:$D,Яндекс!$A:$A,"Купить",Яндекс!$B:$B,"Квартира в новостройке",Яндекс!$C:$C,$C22) | F22: =SUMIFS(Авито!$E:$E,Авито!$A:$A,"Продажа",Авито!$B:$B,"Квартиры новостройка",Авито!$C:$C,$C22) | G22: =SUMIFS(Домклик!$D:$D,Домклик!$A:$A,"Покупка",Домклик!$B:$B,"Квартиры новостройки",Домклик!$C:$C,$C22) | H22: =IFERROR(INDEX($D$1:$G$1,MATCH(MAX(D22:G22),D22:G22,0)),"")
A23: Продажа | B23: Квартиры — новостройки | C23: Екатеринбург | D23: =SUMIFS(ЦИАН!$D:$D,ЦИАН!$A:$A,"Продажи квартир",ЦИАН!$B:$B,"Квартиры в новостройках",ЦИАН!$C:$C,$C23) | E23: =SUMIFS(Яндекс!$D:$D,Яндекс!$A:$A,"Купить",Яндекс!$B:$B,"Квартира в новостройке",Яндекс!$C:$C,$C23) | F23: =SUMIFS(Авито!$E:$E,Авито!$A:$A,"Продажа",Авито!$B:$B,"Квартиры новостройка",Авито!$C:$C,$C23) | G23: =SUMIFS(Домклик!$D:$D,Домклик!$A:$A,"Покупка",Домклик!$B:$B,"Квартиры новостройки",Домклик!$C:$C,$C23) | H23: =IFERROR(INDEX($D$1:$G$1,MATCH(MAX(D23:G23),D23:G23,0)),"")
A24: Продажа | B24: Квартиры — новостройки | C24: Казань | D24: =SUMIFS(ЦИАН!$D:$D,ЦИАН!$A:$A,"Продажи квартир",ЦИАН!$B:$B,"Квартиры в новостройках",ЦИАН!$C:$C,$C24) | E24: =SUMIFS(Яндекс!$D:$D,Яндекс!$A:$A,"Купить",Яндекс!$B:$B,"Квартира в новостройке",Яндекс!$C:$C,$C24) | F24: =SUMIFS(Авито!$E:$E,Авито!$A:$A,"Продажа",Авито!$B:$B,"Квартиры новостройка",Авито!$C:$C,$C24) | G24: =SUMIFS(Домклик!$D:$D,Домклик!$A:$A,"Покупка",Домклик!$B:$B,"Квартиры новостройки",Домклик!$C:$C,$C24) | H24: =IFERROR(INDEX($D$1:$G$1,MATCH(MAX(D24:G24),D24:G24,0)),"")
A25: Продажа | B25: Квартиры — новостройки | C25: Красноярск | D25: =SUMIFS(ЦИАН!$D:$D,ЦИАН!$A:$A,"Продажи квартир",ЦИАН!$B:$B,"Квартиры в новостройках",ЦИАН!$C:$C,$C25) | E25: =SUMIFS(Яндекс!$D:$D,Яндекс!$A:$A,"Купить",Яндекс!$B:$B,"Квартира в новостройке",Яндекс!$C:$C,$C25) | F25: =SUMIFS(Авито!$E:$E,Авито!$A:$A,"Продажа",Авито!$B:$B,"Квартиры новостройка",Авито!$C:$C,$C25) | G25: =SUMIFS(Домклик!$D:$D,Домклик!$A:$A,"Покупка",Домклик!$B:$B,"Квартиры новостройки",Домклик!$C:$C,$C25) | H25: =IFERROR(INDEX($D$1:$G$1,MATCH(MAX(D25:G25),D25:G25,0)),"")
A26: Продажа | B26: Квартиры — новостройки | C26: Нижний Новгород | D26: =SUMIFS(ЦИАН!$D:$D,ЦИАН!$A:$A,"Продажи квартир",ЦИАН!$B:$B,"Квартиры в новостройках",ЦИАН!$C:$C,$C26) | E26: =SUMIFS(Яндекс!$D:$D,Яндекс!$A:$A,"Купить",Яндекс!$B:$B,"Квартира в новостройке",Яндекс!$C:$C,$C26) | F26: =SUMIFS(Авито!$E:$E,Авито!$A:$A,"Продажа",Авито!$B:$B,"Квартиры новостройка",Авито!$C:$C,$C26) | G26: =SUMIFS(Домклик!$D:$D,Домклик!$A:$A,"Покупка",Домклик!$B:$B,"Квартиры новостройки",Домклик!$C:$C,$C26) | H26: =IFERROR(INDEX($D$1:$G$1,MATCH(MAX(D26:G26),D26:G26,0)),"")
A27: Продажа | B27: Квартиры — новостройки | C27: Челябинск | D27: =SUMIFS(ЦИАН!$D:$D,ЦИАН!$A:$A,"Продажи квартир",ЦИАН!$B:$B,"Квартиры в новостройках",ЦИАН!$C:$C,$C27) | E27: =SUMIFS(Яндекс!$D:$D,Яндекс!$A:$A,"Купить",Яндекс!$B:$B,"Квартира в новостройке",Яндекс!$C:$C,$C27) | F27: =SUMIFS(Авито!$E:$E,Авито!$A:$A,"Продажа",Авито!$B:$B,"Квартиры новостройка",Авито!$C:$C,$C27) | G27: =SUMIFS(Домклик!$D:$D,Домклик!$A:$A,"Покупка",Домклик!$B:$B,"Квартиры новостройки",Домклик!$C:$C,$C27) | H27: =IFERROR(INDEX($D$1:$G$1,MATCH(MAX(D27:G27),D27:G27,0)),"")
A28: Продажа | B28: Квартиры — новостройки | C28: Уфа | D28: =SUMIFS(ЦИАН!$D:$D,ЦИАН!$A:$A,"Продажи квартир",ЦИАН!$B:$B,"Квартиры в новостройках",ЦИАН!$C:$C,$C28) | E28: =SUMIFS(Яндекс!$D:$D,Яндекс!$A:$A,"Купить",Яндекс!$B:$B,"Квартира в новостройке",Яндекс!$C:$C,$C28) | F28: =SUMIFS(Авито!$E:$E,Авито!$A:$A,"Продажа",Авито!$B:$B,"Квартиры новостройка",Авито!$C:$C,$C28) | G28: =SUMIFS(Домклик!$D:$D,Домклик!$A:$A,"Покупка",Домклик!$B:$B,"Квартиры новостройки",Домклик!$C:$C,$C28) | H28: =IFERROR(INDEX($D$1:$G$1,MATCH(MAX(D28:G28),D28:G28,0)),"")
A29: Продажа | B29: Квартиры — новостройки | C29: Краснодар | D29: =SUMIFS(ЦИАН!$D:$D,ЦИАН!$A:$A,"Продажи квартир",ЦИАН!$B:$B,"Квартиры в новостройках",ЦИАН!$C:$C,$C29) | E29: =SUMIFS(Яндекс!$D:$D,Яндекс!$A:$A,"Купить",Яндекс!$B:$B,"Квартира в новостройке",Яндекс!$C:$C,$C29) | F29: =SUMIFS(Авито!$E:$E,Авито!$A:$A,"Продажа",Авито!$B:$B,"Квартиры новостройка",Авито!$C:$C,$C29) | G29: =SUMIFS(Домклик!$D:$D,Домклик!$A:$A,"Покупка",Домклик!$B:$B,"Квартиры новостройки",Домклик!$C:$C,$C29) | H29: =IFERROR(INDEX($D$1:$G$1,MATCH(MAX(D29:G29),D29:G29,0)),"")
A30: Продажа | B30: Квартиры — новостройки | C30: Самара | D30: =SUMIFS(ЦИАН!$D:$D,ЦИАН!$A:$A,"Продажи квартир",ЦИАН!$B:$B,"Квартиры в новостройках",ЦИАН!$C:$C,$C30) | E30: =SUMIFS(Яндекс!$D:$D,Яндекс!$A:$A,"Купить",Яндекс!$B:$B,"Квартира в новостройке",Яндекс!$C:$C,$C30) | F30: =SUMIFS(Авито!$E:$E,Авито!$A:$A,"Продажа",Авито!$B:$B,"Квартиры новостройка",Авито!$C:$C,$C30) | G30: =SUMIFS(Домклик!$D:$D,Домклик!$A:$A,"Покупка",Домклик!$B:$B,"Квартиры новостройки",Домклик!$C:$C,$C30) | H30: =IFERROR(INDEX($D$1:$G$1,MATCH(MAX(D30:G30),D30:G30,0)),"")
... A35: Продажа | B35: Квартиры — новостройки | C35: Волгоград | D35: =SUMIFS(ЦИАН!$D:$D,ЦИАН!$A:$A,"Продажи квартир",ЦИАН!$B:$B,"Квартиры в новостройках",ЦИАН!$C:$C,$C35) | E35: =SUMIFS(Яндекс!$D:$D,Яндекс!$A:$A,"Купить",Яндекс!$B:$B,"Квартира в новостройке",Яндекс!$C:$C,$C35) | F35: =SUMIFS(Авито!$E:$E,Авито!$A:$A,"Продажа",Авито!$B:$B,"Квартиры новостройка",Авито!$C:$C,$C35) | G35: =SUMIFS(Домклик!$D:$D,Домклик!$A:$A,"Покупка",Домклик!$B:$B,"Квартиры новостройки",Домклик!$C:$C,$C35) | H35: =IFERROR(INDEX($D$1:$G$1,MATCH(MAX(D35:G35),D35:G35,0)),"")
A36: Продажа | B36: Квартиры — вторичка | C36: 🇷🇺 Вся Россия | D36: =SUMIFS(ЦИАН!$D:$D,ЦИАН!$A:$A,"Продажи квартир",ЦИАН!$B:$B,"Квартиры во вторичке",ЦИАН!$C:$C,$C36) | E36: =SUMIFS(Яндекс!$D:$D,Яндекс!$A:$A,"Купить",Яндекс!$B:$B,"Квартира во вторичке",Яндекс!$C:$C,$C36) | F36: =SUMIFS(Авито!$E:$E,Авито!$A:$A,"Продажа",Авито!$B:$B,"Квартиры вторичка",Авито!$C:$C,$C36) | G36: =SUMIFS(Домклик!$D:$D,Домклик!$A:$A,"Покупка",Домклик!$B:$B,"Квартиры вторичка",Домклик!$C:$C,$C36) | H36: =IFERROR(INDEX($D$1:$G$1,MATCH(MAX(D36:G36),D36:G36,0)),"")
A37: Продажа | B37: Квартиры — вторичка | C37: Москва | D37: =SUMIFS(ЦИАН!$D:$D,ЦИАН!$A:$A,"Продажи квартир",ЦИАН!$B:$B,"Квартиры во вторичке",ЦИАН!$C:$C,$C37) | E37: =SUMIFS(Яндекс!$D:$D,Яндекс!$A:$A,"Купить",Яндекс!$B:$B,"Квартира во вторичке",Яндекс!$C:$C,$C37) | F37: =SUMIFS(Авито!$E:$E,Авито!$A:$A,"Продажа",Авито!$B:$B,"Квартиры вторичка",Авито!$C:$C,$C37) | G37: =SUMIFS(Домклик!$D:$D,Домклик!$A:$A,"Покупка",Домклик!$B:$B,"Квартиры вторичка",Домклик!$C:$C,$C37) | H37: =IFERROR(INDEX($D$1:$G$1,MATCH(MAX(D37:G37),D37:G37,0)),"")
A38: Продажа | B38: Квартиры — вторичка | C38: Санкт-Петербург | D38: =SUMIFS(ЦИАН!$D:$D,ЦИАН!$A:$A,"Продажи квартир",ЦИАН!$B:$B,"Квартиры во вторичке",ЦИАН!$C:$C,$C38) | E38: =SUMIFS(Яндекс!$D:$D,Яндекс!$A:$A,"Купить",Яндекс!$B:$B,"Квартира во вторичке",Яндекс!$C:$C,$C38) | F38: =SUMIFS(Авито!$E:$E,Авито!$A:$A,"Продажа",Авито!$B:$B,"Квартиры вторичка",Авито!$C:$C,$C38) | G38: =SUMIFS(Домклик!$D:$D,Домклик!$A:$A,"Покупка",Домклик!$B:$B,"Квартиры вторичка",Домклик!$C:$C,$C38) | H38: =IFERROR(INDEX($D$1:$G$1,MATCH(MAX(D38:G38),D38:G38,0)),"")
A39: Продажа | B39: Квартиры — вторичка | C39: Новосибирск | D39: =SUMIFS(ЦИАН!$D:$D,ЦИАН!$A:$A,"Продажи квартир",ЦИАН!$B:$B,"Квартиры во вторичке",ЦИАН!$C:$C,$C39) | E39: =SUMIFS(Яндекс!$D:$D,Яндекс!$A:$A,"Купить",Яндекс!$B:$B,"Квартира во вторичке",Яндекс!$C:$C,$C39) | F39: =SUMIFS(Авито!$E:$E,Авито!$A:$A,"Продажа",Авито!$B:$B,"Квартиры вторичка",Авито!$C:$C,$C39) | G39: =SUMIFS(Домклик!$D:$D,Домклик!$A:$A,"Покупка",Домклик!$B:$B,"Квартиры вторичка",Домклик!$C:$C,$C39) | H39: =IFERROR(INDEX($D$1:$G$1,MATCH(MAX(D39:G39),D39:G39,0)),"")
A40: Продажа | B40: Квартиры — вторичка | C40: Екатеринбург | D40: =SUMIFS(ЦИАН!$D:$D,ЦИАН!$A:$A,"Продажи квартир",ЦИАН!$B:$B,"Квартиры во вторичке",ЦИАН!$C:$C,$C40) | E40: =SUMIFS(Яндекс!$D:$D,Яндекс!$A:$A,"Купить",Яндекс!$B:$B,"Квартира во вторичке",Яндекс!$C:$C,$C40) | F40: =SUMIFS(Авито!$E:$E,Авито!$A:$A,"Продажа",Авито!$B:$B,"Квартиры вторичка",Авито!$C:$C,$C40) | G40: =SUMIFS(Домклик!$D:$D,Домклик!$A:$A,"Покупка",Домклик!$B:$B,"Квартиры вторичка",Домклик!$C:$C,$C40) | H40: =IFERROR(INDEX($D$1:$G$1,MATCH(MAX(D40:G40),D40:G40,0)),"")
A41: Продажа | B41: Квартиры — вторичка | C41: Казань | D41: =SUMIFS(ЦИАН!$D:$D,ЦИАН!$A:$A,"Продажи квартир",ЦИАН!$B:$B,"Квартиры во вторичке",ЦИАН!$C:$C,$C41) | E41: =SUMIFS(Яндекс!$D:$D,Яндекс!$A:$A,"Купить",Яндекс!$B:$B,"Квартира во вторичке",Яндекс!$C:$C,$C41) | F41: =SUMIFS(Авито!$E:$E,Авито!$A:$A,"Продажа",Авито!$B:$B,"Квартиры вторичка",Авито!$C:$C,$C41) | G41: =SUMIFS(Домклик!$D:$D,Домклик!$A:$A,"Покупка",Домклик!$B:$B,"Квартиры вторичка",Домклик!$C:$C,$C41) | H41: =IFERROR(INDEX($D$1:$G$1,MATCH(MAX(D41:G41),D41:G41,0)),"")
A42: Продажа | B42: Квартиры — вторичка | C42: Красноярск | D42: =SUMIFS(ЦИАН!$D:$D,ЦИАН!$A:$A,"Продажи квартир",ЦИАН!$B:$B,"Квартиры во вторичке",ЦИАН!$C:$C,$C42) | E42: =SUMIFS(Яндекс!$D:$D,Яндекс!$A:$A,"Купить",Яндекс!$B:$B,"Квартира во вторичке",Яндекс!$C:$C,$C42) | F42: =SUMIFS(Авито!$E:$E,Авито!$A:$A,"Продажа",Авито!$B:$B,"Квартиры вторичка",Авито!$C:$C,$C42) | G42: =SUMIFS(Домклик!$D:$D,Домклик!$A:$A,"Покупка",Домклик!$B:$B,"Квартиры вторичка",Домклик!$C:$C,$C42) | H42: =IFERROR(INDEX($D$1:$G$1,MATCH(MAX(D42:G42),D42:G42,0)),"")
A43: Продажа | B43: Квартиры — вторичка | C43: Нижний Новгород | D43: =SUMIFS(ЦИАН!$D:$D,ЦИАН!$A:$A,"Продажи квартир",ЦИАН!$B:$B,"Квартиры во вторичке",ЦИАН!$C:$C,$C43) | E43: =SUMIFS(Яндекс!$D:$D,Яндекс!$A:$A,"Купить",Яндекс!$B:$B,"Квартира во вторичке",Яндекс!$C:$C,$C43) | F43: =SUMIFS(Авито!$E:$E,Авито!$A:$A,"Продажа",Авито!$B:$B,"Квартиры вторичка",Авито!$C:$C,$C43) | G43: =SUMIFS(Домклик!$D:$D,Домклик!$A:$A,"Покупка",Домклик!$B:$B,"Квартиры вторичка",Домклик!$C:$C,$C43) | H43: =IFERROR(INDEX($D$1:$G$1,MATCH(MAX(D43:G43),D43:G43,0)),"")
A44: Продажа | B44: Квартиры — вторичка | C44: Челябинск | D44: =SUMIFS(ЦИАН!$D:$D,ЦИАН!$A:$A,"Продажи квартир",ЦИАН!$B:$B,"Квартиры во вторичке",ЦИАН!$C:$C,$C44) | E44: =SUMIFS(Яндекс!$D:$D,Яндекс!$A:$A,"Купить",Яндекс!$B:$B,"Квартира во вторичке",Яндекс!$C:$C,$C44) | F44: =SUMIFS(Авито!$E:$E,Авито!$A:$A,"Продажа",Авито!$B:$B,"Квартиры вторичка",Авито!$C:$C,$C44) | G44: =SUMIFS(Домклик!$D:$D,Домклик!$A:$A,"Покупка",Домклик!$B:$B,"Квартиры вторичка",Домклик!$C:$C,$C44) | H44: =IFERROR(INDEX($D$1:$G$1,MATCH(MAX(D44:G44),D44:G44,0)),"")
A45: Продажа | B45: Квартиры — вторичка | C45: Уфа | D45: =SUMIFS(ЦИАН!$D:$D,ЦИАН!$A:$A,"Продажи квартир",ЦИАН!$B:$B,"Квартиры во вторичке",ЦИАН!$C:$C,$C45) | E45: =SUMIFS(Яндекс!$D:$D,Яндекс!$A:$A,"Купить",Яндекс!$B:$B,"Квартира во вторичке",Яндекс!$C:$C,$C45) | F45: =SUMIFS(Авито!$E:$E,Авито!$A:$A,"Продажа",Авито!$B:$B,"Квартиры вторичка",Авито!$C:$C,$C45) | G45: =SUMIFS(Домклик!$D:$D,Домклик!$A:$A,"Покупка",Домклик!$B:$B,"Квартиры вторичка",Домклик!$C:$C,$C45) | H45: =IFERROR(INDEX($D$1:$G$1,MATCH(MAX(D45:G45),D45:G45,0)),"")
A46: Продажа | B46: Квартиры — вторичка | C46: Краснодар | D46: =SUMIFS(ЦИАН!$D:$D,ЦИАН!$A:$A,"Продажи квартир",ЦИАН!$B:$B,"Квартиры во вторичке",ЦИАН!$C:$C,$C46) | E46: =SUMIFS(Яндекс!$D:$D,Яндекс!$A:$A,"Купить",Яндекс!$B:$B,"Квартира во вторичке",Яндекс!$C:$C,$C46) | F46: =SUMIFS(Авито!$E:$E,Авито!$A:$A,"Продажа",Авито!$B:$B,"Квартиры вторичка",Авито!$C:$C,$C46) | G46: =SUMIFS(Домклик!$D:$D,Домклик!$A:$A,"Покупка",Домклик!$B:$B,"Квартиры вторичка",Домклик!$C:$C,$C46) | H46: =IFERROR(INDEX($D$1:$G$1,MATCH(MAX(D46:G46),D46:G46,0)),"")
A47: Продажа | B47: Квартиры — вторичка | C47: Самара | D47: =SUMIFS(ЦИАН!$D:$D,ЦИАН!$A:$A,"Продажи квартир",ЦИАН!$B:$B,"Квартиры во вторичке",ЦИАН!$C:$C,$C47) | E47: =SUMIFS(Яндекс!$D:$D,Яндекс!$A:$A,"Купить",Яндекс!$B:$B,"Квартира во вторичке",Яндекс!$C:$C,$C47) | F47: =SUMIFS(Авито!$E:$E,Авито!$A:$A,"Продажа",Авито!$B:$B,"Квартиры вторичка",Авито!$C:$C,$C47) | G47: =SUMIFS(Домклик!$D:$D,Домклик!$A:$A,"Покупка",Домклик!$B:$B,"Квартиры вторичка",Домклик!$C:$C,$C47) | H47: =IFERROR(INDEX($D$1:$G$1,MATCH(MAX(D47:G47),D47:G47,0)),"")
... A52: Продажа | B52: Квартиры — вторичка | C52: Волгоград | D52: =SUMIFS(ЦИАН!$D:$D,ЦИАН!$A:$A,"Продажи квартир",ЦИАН!$B:$B,"Квартиры во вторичке",ЦИАН!$C:$C,$C52) | E52: =SUMIFS(Яндекс!$D:$D,Яндекс!$A:$A,"Купить",Яндекс!$B:$B,"Квартира во вторичке",Яндекс!$C:$C,$C52) | F52: =SUMIFS(Авито!$E:$E,Авито!$A:$A,"Продажа",Авито!$B:$B,"Квартиры вторичка",Авито!$C:$C,$C52) | G52: =SUMIFS(Домклик!$D:$D,Домклик!$A:$A,"Покупка",Домклик!$B:$B,"Квартиры вторичка",Домклик!$C:$C,$C52) | H52: =IFERROR(INDEX($D$1:$G$1,MATCH(MAX(D52:G52),D52:G52,0)),"")
...

Sheet ЦИАН
A1: Группа | B1: Категория | C1: Город | D1: 2026-06-10
A2: Аренда квартир | B2: Длительная: Квартиры | C2: 🇷🇺 Вся Россия | D2: 125508
A3: Аренда квартир | B3: Длительная: Квартиры | C3: Москва | D3: 27204
A4: Аренда квартир | B4: Длительная: Квартиры | C4: Санкт-Петербург | D4: 9761
A5: Аренда квартир | B5: Длительная: Квартиры | C5: Новосибирск | D5: 4836
A6: Аренда квартир | B6: Длительная: Квартиры | C6: Екатеринбург | D6: 3235
A7: Аренда квартир | B7: Длительная: Квартиры | C7: Казань | D7: 3843
A8: Аренда квартир | B8: Длительная: Квартиры | C8: Красноярск | D8: 1825
A9: Аренда квартир | B9: Длительная: Квартиры | C9: Нижний Новгород | D9: 1427
A10: Аренда квартир | B10: Длительная: Квартиры | C10: Челябинск | D10: 1394
A11: Аренда квартир | B11: Длительная: Квартиры | C11: Уфа | D11: 1831
A12: Аренда квартир | B12: Длительная: Квартиры | C12: Краснодар | D12: 5854
A13: Аренда квартир | B13: Длительная: Квартиры | C13: Самара | D13: 1163
... A355: Коммерческая · Спец-объекты | B355: Складские комплексы | C355: Волгоград | D355: 5
A357: Итого (по фильтру) | C357: ← сумма видимых строк (без «Вся Россия») | D357: =SUMPRODUCT(SUBTOTAL(109,OFFSET(D$2,ROW(D$2:D$355)-ROW(D$2),0)),--($C$2:$C$355<>"🇷🇺 Вся Россия"))

Sheet Вся Россия (регионы)
A1: Группа | B1: Категория | C1: Регион | D1: 2026-06-10
A2: Аренда квартир | B2: Длительная: Квартиры | C2: Москва | D2: 27241
A3: Аренда квартир | B3: Длительная: Квартиры | C3: Санкт-Петербург | D3: 9781
A4: Аренда квартир | B4: Длительная: Квартиры | C4: Республика Адыгея | D4: 372
A5: Аренда квартир | B5: Длительная: Квартиры | C5: Республика Алтай | D5: 27
A6: Аренда квартир | B6: Длительная: Квартиры | C6: Алтайский край | D6: 570
A7: Аренда квартир | B7: Длительная: Квартиры | C7: Амурская область | D7: 107
A8: Аренда квартир | B8: Длительная: Квартиры | C8: Архангельская область | D8: 173
A9: Аренда квартир | B9: Длительная: Квартиры | C9: Астраханская область | D9: 358
A10: Аренда квартир | B10: Длительная: Квартиры | C10: Республика Башкортостан | D10: 2052
A11: Аренда квартир | B11: Длительная: Квартиры | C11: Белгородская область | D11: 4156
A12: Аренда квартир | B12: Длительная: Квартиры | C12: Брянская область | D12: 399
A13: Аренда квартир | B13: Длительная: Квартиры | C13: Республика Бурятия | D13: 149
... A1531: Коммерческая · Продажа | B1531: Бизнес (готовый) | C1531: Забайкальский край | D1531: 24
A1533: Итого (по фильтру) | D1533: =SUBTOTAL(109,D2:D1531)

Sheet CIAN Price
A1: Сделка | B1: Тип недвижимости | C1: Категория | D1: Город | E1: Публикация, ₽/30 дн | F1: Топ, ₽/сут | G1: Премиум, ₽/сут | H1: Стандарт, ₽/сут | I1: Примечание | J1: Обновлено
A2: Продажа | B2: Городская | C2: Квартира | D2: Москва | E2: 3390 | F2: 1213 | G2: 492 | H2: 162 | I2: Цена зависит от стоимости объекта | J2: 2026-06-10
A3: Продажа | B3: Городская | C3: Квартира | D3: Санкт-Петербург | E3: 1560 | F3: 598 | G3: 255 | H3: 108 | I3: Цена зависит от стоимости объекта | J3: 2026-06-10
A4: Продажа | B4: Городская | C4: Квартира | D4: Новосибирск | E4: 1596 | F4: 420 | G4: 189 | H4: 56 | I4: Цена зависит от стоимости объекта | J4: 2026-06-10
A5: Продажа | B5: Городская | C5: Квартира | D5: Екатеринбург | E5: 489 | F5: 396 | G5: 205 | H5: 62 | I5: Цена зависит от стоимости объекта | J5: 2026-06-10
A6: Продажа | B6: Городская | C6: Квартира | D6: Казань | E6: 354 | F6: 222 | G6: 86 | H6: 25 | I6: Цена зависит от стоимости объекта | J6: 2026-06-10
A7: Продажа | B7: Городская | C7: Квартира | D7: Красноярск | E7: 573 | F7: — | G7: — | H7: — | I7: Цена зависит от стоимости объекта | J7: 2026-06-10
A8: Продажа | B8: Городская | C8: Квартира | D8: Нижний Новгород | E8: 441 | F8: 208 | G8: 81 | H8: 23 | I8: Цена зависит от стоимости объекта | J8: 2026-06-10
A9: Продажа | B9: Городская | C9: Квартира | D9: Челябинск | E9: 291 | F9: 203 | G9: 95 | H9: 27 | I9: Цена зависит от стоимости объекта | J9: 2026-06-10
A10: Продажа | B10: Городская | C10: Квартира | D10: Уфа | E10: 213 | F10: 176 | G10: 80 | H10: 23 | I10: Цена зависит от стоимости объекта | J10: 2026-06-10
A11: Продажа | B11: Городская | C11: Квартира | D11: Краснодар | E11: 468 | F11: 197 | G11: 79 | H11: 24 | I11: Цена зависит от стоимости объекта | J11: 2026-06-10
A12: Продажа | B12: Городская | C12: Квартира | D12: Самара | E12: 354 | F12: — | G12: — | H12: — | I12: Цена зависит от стоимости объекта | J12: 2026-06-10
A13: Продажа | B13: Городская | C13: Квартира | D13: Ростов-на-Дону | E13: 468 | F13: 214 | G13: 87 | H13: 26 | I13: Цена зависит от стоимости объекта | J13: 2026-06-10
A14: Продажа | B14: Городская | C14: Квартира | D14: Омск | E14: 780 | F14: 345 | G14: 187 | H14: 58 | I14: Цена зависит от стоимости объекта | J14: 2026-06-10
A15: Продажа | B15: Городская | C15: Квартира | D15: Воронеж | E15: 204 | F15: — | G15: — | H15: — | I15: Цена зависит от стоимости объекта | J15: 2026-06-10
A16: Продажа | B16: Городская | C16: Квартира | D16: Пермь | E16: 99 | F16: — | G16: — | H16: — | I16: Цена зависит от стоимости объекта | J16: 2026-06-10
A17: Продажа | B17: Городская | C17: Квартира | D17: Волгоград | E17: 303 | F17: — | G17: — | H17: — | I17: Цена зависит от стоимости объекта | J17: 2026-06-10
A18: Продажа | B18: Городская | C18: Комната | D18: Москва | E18: 3120 | F18: 904 | G18: 382 | H18: 116 | I18: Цена зависит от стоимости объекта | J18: 2026-06-10
A19: Продажа | B19: Городская | C19: Комната | D19: Санкт-Петербург | E19: 1350 | F19: 471 | G19: 208 | H19: 64 | I19: Цена зависит от стоимости объекта | J19: 2026-06-10
A20: Продажа | B20: Городская | C20: Комната | D20: Новосибирск | E20: 1332 | F20: 315 | G20: 148 | H20: 45 | I20: Цена зависит от стоимости объекта | J20: 2026-06-10
A21: Продажа | B21: Городская | C21: Комната | D21: Екатеринбург | E21: 489 | F21: 284 | G21: 155 | H21: 46 | I21: Цена зависит от стоимости объекта | J21: 2026-06-10
A22: Продажа | B22: Городская | C22: Комната | D22: Казань | E22: 315 | F22: 179 | G22: 70 | H22: 20 | I22: Цена зависит от стоимости объекта | J22: 2026-06-10
A23: Продажа | B23: Городская | C23: Комната | D23: Красноярск | E23: 513 | F23: — | G23: — | H23: — | I23: Цена зависит от стоимости объекта | J23: 2026-06-10
A24: Продажа | B24: Городская | C24: Комната | D24: Нижний Новгород | E24: 390 | F24: 159 | G24: 66 | H24: 20 | I24: Цена зависит от стоимости объекта | J24: 2026-06-10
A25: Продажа | B25: Городская | C25: Комната | D25: Челябинск | E25: 171 | F25: 207 | G25: 100 | H25: 29 | I25: Цена зависит от стоимости объекта | J25: 2026-06-10
A26: Продажа | B26: Городская | C26: Комната | D26: Уфа | E26: 225 | F26: 178 | G26: 80 | H26: 23 | I26: Цена зависит от стоимости объекта | J26: 2026-06-10
A27: Продажа | B27: Городская | C27: Комната | D27: Краснодар | E27: 342 | F27: 141 | G27: 60 | H27: 18 | I27: Цена зависит от стоимости объекта | J27: 2026-06-10
A28: Продажа | B28: Городская | C28: Комната | D28: Самара | E28: 192 | F28: — | G28: — | H28: — | I28: Цена зависит от стоимости объекта | J28: 2026-06-10
A29: Продажа | B29: Городская | C29: Комната | D29: Ростов-на-Дону | E29: 468 | F29: 182 | G29: 74 | H29: 22 | I29: Цена зависит от стоимости объекта | J29: 2026-06-10
A30: Продажа | B30: Городская | C30: Комната | D30: Омск | E30: 798 | F30: 345 | G30: 196 | H30: 60 | I30: Цена зависит от стоимости объекта | J30: 2026-06-10
A31: Продажа | B31: Городская | C31: Комната | D31: Воронеж | E31: 126 | F31: — | G31: — | H31: — | I31: Цена зависит от стоимости объекта | J31: 2026-06-10
A32: Продажа | B32: Городская | C32: Комната | D32: Пермь | E32: 99 | F32: — | G32: — | H32: — | I32: Цена зависит от стоимости объекта | J32: 2026-06-10
A33: Продажа | B33: Городская | C33: Комната | D33: Волгоград | E33: 246 | F33: — | G33: — | H33: — | I33: Цена зависит от стоимости объекта | J33: 2026-06-10
A34: Продажа | B34: Городская | C34: Квартира в новостройке | D34: Москва | E34: 3390 | F34: 1213 | G34: 492 | H34: 162 | I34: Цена зависит от стоимости объекта | J34: 2026-06-10
A35: Продажа | B35: Городская | C35: Квартира в новостройке | D35: Санкт-Петербург | E35: 1560 | F35: 538 | G35: 230 | H35: 97 | I35: Цена зависит от стоимости объекта | J35: 2026-06-10
A36: Продажа | B36: Городская | C36: Квартира в новостройке | D36: Новосибирск | E36: 1596 | F36: 357 | G36: 161 | H36: 48 | I36: Цена зависит от стоимости объекта | J36: 2026-06-10
A37: Продажа | B37: Городская | C37: Квартира в новостройке | D37: Екатеринбург | E37: 489 | F37: 390 | G37: 194 | H37: 59 | I37: Цена зависит от стоимости объекта | J37: 2026-06-10
A38: Продажа | B38: Городская | C38: Квартира в новостройке | D38: Казань | E38: 354 | F38: 222 | G38: 86 | H38: 25 | I38: Цена зависит от стоимости объекта | J38: 2026-06-10
A39: Продажа | B39: Городская | C39: Квартира в новостройке | D39: Красноярск | E39: 573 | F39: — | G39: — | H39: — | I39: Цена зависит от стоимости объекта | J39: 2026-06-10
A40: Продажа | B40: Городская | C40: Квартира в новостройке | D40: Нижний Новгород | E40: 441 | F40: 190 | G40: 72 | H40: 22 | I40: Цена зависит от стоимости объекта | J40: 2026-06-10
...

Sheet Яндекс
A1: Группа | B1: Категория | C1: Город | D1: 2026-06-11
A2: Купить | B2: Квартира | C2: 🇷🇺 Вся Россия | D2: 925191
A3: Купить | B3: Квартира | C3: Москва | D3: 69187
A4: Купить | B4: Квартира | C4: Санкт-Петербург | D4: 39444
A5: Купить | B5: Квартира | C5: Новосибирск | D5: 31864
A6: Купить | B6: Квартира | C6: Екатеринбург | D6: 38343
A7: Купить | B7: Квартира | C7: Казань | D7: 18334
A8: Купить | B8: Квартира | C8: Красноярск | D8: —
A9: Купить | B9: Квартира | C9: Нижний Новгород | D9: 10203
A10: Купить | B10: Квартира | C10: Челябинск | D10: 6426
A11: Купить | B11: Квартира | C11: Уфа | D11: 18896
A12: Купить | B12: Квартира | C12: Краснодар | D12: 68429
A13: Купить | B13: Квартира | C13: Самара | D13: 6124
A14: Купить | B14: Квартира | C14: Ростов-на-Дону | D14: 46684
A15: Купить | B15: Квартира | C15: Омск | D15: 5009
A16: Купить | B16: Квартира | C16: Воронеж | D16: 13990
A17: Купить | B17: Квартира | C17: Пермь | D17: 14018
A18: Купить | B18: Квартира | C18: Волгоград | D18: 8860
A19: Купить | B19: Квартира в новостройке | C19: 🇷🇺 Вся Россия | D19: 547731
A20: Купить | B20: Квартира в новостройке | C20: Москва | D20: 48774
... A239: Коммерческая | B239: Аренда | C239: Волгоград | D239: 462
A241: Итого (по фильтру) | C241: ← сумма видимых строк (без «Вся Россия») | D241: =SUMPRODUCT(SUBTOTAL(109,OFFSET(D$2,ROW(D$2:D$239)-ROW(D$2),0)),--($C$2:$C$239<>"🇷🇺 Вся Россия"))

Sheet Авито
A1: Группа | B1: Категория | C1: Город | D1: 2026-06-11 | E1: 2026-06-12
A2: Продажа | B2: Квартиры | C2: 🇷🇺 Вся Россия | D2: 1475674 | E2: 1463127
A3: Продажа | B3: Квартиры | C3: Москва | D3: 69503 | E3: 69897
A4: Продажа | B4: Квартиры | C4: Санкт-Петербург | D4: 59698 | E4: 59674
A5: Продажа | B5: Квартиры | C5: Новосибирск | D5: 25738 | E5: 26305
A6: Продажа | B6: Квартиры | C6: Екатеринбург | D6: 51974 | E6: 51802
A7: Продажа | B7: Квартиры | C7: Казань | D7: 28365 | E7: 28308
A8: Продажа | B8: Квартиры | C8: Красноярск | D8: 20160 | E8: 20148
A9: Продажа | B9: Квартиры | C9: Нижний Новгород | D9: 12294 | E9: 12413
A10: Продажа | B10: Квартиры | C10: Челябинск | D10: 17205 | E10: 15543
A11: Продажа | B11: Квартиры | C11: Уфа | D11: 24237 | E11: 24198
A12: Продажа | B12: Квартиры | C12: Краснодар | D12: 66810 | E12: 66651
A13: Продажа | B13: Квартиры | C13: Самара | D13: 8317 | E13: 8301
... A137: Аренда | B137: Квартиры | C137: Волгоград | D137: 5196 | E137: 5182
A138: Аренда | B138: Квартиры долгосрочно | C138: 🇷🇺 Вся Россия | E138: 170002
A139: Аренда | B139: Квартиры долгосрочно | C139: Москва | E139: 17890
A140: Аренда | B140: Квартиры долгосрочно | C140: Санкт-Петербург | E140: 11104
A141: Аренда | B141: Квартиры долгосрочно | C141: Новосибирск | E141: 6016
A142: Аренда | B142: Квартиры долгосрочно | C142: Екатеринбург | E142: 5202
A143: Аренда | B143: Квартиры долгосрочно | C143: Казань | E143: 3609
A144: Аренда | B144: Квартиры долгосрочно | C144: Красноярск | E144: 1625
A145: Аренда | B145: Квартиры долгосрочно | C145: Нижний Новгород | E145: 1881
A146: Аренда | B146: Квартиры долгосрочно | C146: Челябинск | E146: 2436
A147: Аренда | B147: Квартиры долгосрочно | C147: Уфа | E147: 2918
A148: Аренда | B148: Квартиры долгосрочно | C148: Краснодар | E148: 7626
A149: Аренда | B149: Квартиры долгосрочно | C149: Самара | E149: 1837
... A171: Аренда | B171: Квартиры посуточно | C171: Волгоград | E171: 3881
A172: Аренда | B172: Комнаты | C172: 🇷🇺 Вся Россия | D172: 35488 | E172: 35399
A173: Аренда | B173: Комнаты | C173: Москва | D173: 6047 | E173: 5967
A174: Аренда | B174: Комнаты | C174: Санкт-Петербург | D174: 2003 | E174: 1990
A175: Аренда | B175: Комнаты | C175: Новосибирск | D175: 431 | E175: 431
A176: Аренда | B176: Комнаты | C176: Екатеринбург | D176: 527 | E176: 532
A177: Аренда | B177: Комнаты | C177: Казань | D177: 337 | E177: 337
A178: Аренда | B178: Комнаты | C178: Красноярск | D178: 147 | E178: 141
A179: Аренда | B179: Комнаты | C179: Нижний Новгород | D179: 216 | E179: 216
A180: Аренда | B180: Комнаты | C180: Челябинск | D180: 166 | E180: 162
A181: Аренда | B181: Комнаты | C181: Уфа | D181: 171 | E181: 169
A182: Аренда | B182: Комнаты | C182: Краснодар | D182: 342 | E182: 337
A183: Аренда | B183: Комнаты | C183: Самара | D183: 197 | E183: 194
... A239: Аренда | B239: Коммерческая | C239: Волгоград | D239: 1000 | E239: 983
...

Sheet Яндекс регионы
A1: Группа | B1: Категория | C1: Регион | D1: 2026-06-11
A2: Купить | B2: Квартира | C2: Адыгея | D2: 9474
A3: Купить | B3: Квартира | C3: Алтай | D3: 787
A4: Купить | B4: Квартира | C4: Алтайский | D4: 3525
A5: Купить | B5: Квартира | C5: Амурская | D5: 1985
A6: Купить | B6: Квартира | C6: Архангельская | D6: 4850
A7: Купить | B7: Квартира | C7: Астраханская | D7: 5302
A8: Купить | B8: Квартира | C8: Башкортостан | D8: 23898
A9: Купить | B9: Квартира | C9: Белгородская | D9: 5343
A10: Купить | B10: Квартира | C10: Брянская | D10: 4668
A11: Купить | B11: Квартира | C11: Бурятия | D11: 2663
A12: Купить | B12: Квартира | C12: Владимирская | D12: 7918
A13: Купить | B13: Квартира | C13: Волгоградская | D13: 9605
... A1191: Коммерческая | B1191: Аренда | C1191: Ярославская | D1191: 840
A1193: Итого (по фильтру) | C1193: ← сумма видимых строк | D1193: =SUBTOTAL(109,D2:D1191)

Sheet Домклик
A1: Группа | B1: Категория | C1: Город | D1: 2026-06-11 | E1: 2026-06-12
A2: Покупка | B2: Квартиры | C2: 🇷🇺 Вся Россия | D2: 724157 | E2: 720954
A3: Покупка | B3: Квартиры | C3: Москва | D3: 64176
A4: Покупка | B4: Квартиры | C4: Санкт-Петербург | D4: 48234
A5: Покупка | B5: Квартиры | C5: Новосибирск | D5: 23764
A6: Покупка | B6: Квартиры | C6: Екатеринбург | D6: 35000
A7: Покупка | B7: Квартиры | C7: Казань | D7: 14529
A8: Покупка | B8: Квартиры | C8: Красноярск | D8: 14189
A9: Покупка | B9: Квартиры | C9: Нижний Новгород | D9: 9212
A10: Покупка | B10: Квартиры | C10: Челябинск | D10: 10811
A11: Покупка | B11: Квартиры | C11: Уфа | D11: 22529
A12: Покупка | B12: Квартиры | C12: Краснодар | D12: 48810
A13: Покупка | B13: Квартиры | C13: Самара | D13: 10363
A14: Покупка | B14: Квартиры | C14: Ростов-на-Дону | D14: 31328
... A18: Покупка | B18: Квартиры | C18: Волгоград | D18: 8713
A19: Покупка | B19: Квартиры вторичка | C19: 🇷🇺 Вся Россия | D19: 261742 | E19: 258987
A20: Покупка | B20: Квартиры вторичка | C20: Москва | D20: 20462
A21: Покупка | B21: Квартиры вторичка | C21: Санкт-Петербург | D21: 16593
A22: Покупка | B22: Квартиры вторичка | C22: Новосибирск | D22: 8041
A23: Покупка | B23: Квартиры вторичка | C23: Екатеринбург | D23: 6619
A24: Покупка | B24: Квартиры вторичка | C24: Казань | D24: 3572
A25: Покупка | B25: Квартиры вторичка | C25: Красноярск | D25: 5153
A26: Покупка | B26: Квартиры вторичка | C26: Нижний Новгород | D26: 3773
A27: Покупка | B27: Квартиры вторичка | C27: Челябинск | D27: 3897
A28: Покупка | B28: Квартиры вторичка | C28: Уфа | D28: 4582
A29: Покупка | B29: Квартиры вторичка | C29: Краснодар | D29: 14192
A30: Покупка | B30: Квартиры вторичка | C30: Самара | D30: 3440
A31: Покупка | B31: Квартиры вторичка | C31: Ростов-на-Дону | D31: 9162
... A35: Покупка | B35: Квартиры вторичка | C35: Волгоград | D35: 4113
A36: Покупка | B36: Квартиры новостройки | C36: 🇷🇺 Вся Россия | D36: 462416 | E36: 462371
A37: Покупка | B37: Квартиры новостройки | C37: Москва | D37: 43714
A38: Покупка | B38: Квартиры новостройки | C38: Санкт-Петербург | D38: 31641
A39: Покупка | B39: Квартиры новостройки | C39: Новосибирск | D39: 15723
A40: Покупка | B40: Квартиры новостройки | C40: Екатеринбург | D40: 28381
A41: Покупка | B41: Квартиры новостройки | C41: Казань | D41: 10957
A42: Покупка | B42: Квартиры новостройки | C42: Красноярск | D42: 9036
A43: Покупка | B43: Квартиры новостройки | C43: Нижний Новгород | D43: 5439
A44: Покупка | B44: Квартиры новостройки | C44: Челябинск | D44: 6914
A45: Покупка | B45: Квартиры новостройки | C45: Уфа | D45: 17947
A46: Покупка | B46: Квартиры новостройки | C46: Краснодар | D46: 34618
...

Sheet Домклик города (РФ)
A1: Группа | B1: Категория | C1: Город | D1: 2026-06-12
A2: Покупка | B2: Квартиры | C2: Абакан | D2: 3889
A3: Покупка | B3: Квартиры | C3: Анадырь | D3: 43
A4: Покупка | B4: Квартиры | C4: Архангельск | D4: 5313
A5: Покупка | B5: Квартиры | C5: Астрахань | D5: 9000
A6: Покупка | B6: Квартиры | C6: Балашиха | D6: 3215
A7: Покупка | B7: Квартиры | C7: Барнаул | D7: 3333
A8: Покупка | B8: Квартиры | C8: Белгород | D8: 3204
A9: Покупка | B9: Квартиры | C9: Биробиджан | D9: 138
A10: Покупка | B10: Квартиры | C10: Благовещенск | D10: 1611
A11: Покупка | B11: Квартиры | C11: Братск | D11: 688
A12: Покупка | B12: Квартиры | C12: Брянск | D12: 3695
A13: Покупка | B13: Квартиры | C13: Чебоксары | D13: 2705
... A2120: Аренда | B2120: Коммерческая | C2120: Жуковский | D2120: 144
A2122: Итого (по фильтру) | C2122: ← сумма видимых строк | D2122: =SUBTOTAL(109,D2:D2120)

Sheet Avito Price
A1: Город | B1: Публикация 14 дн | C1: Публикация 30 дн | D1: Публикация 60 дн | E1: Продвижение: Оценить (5 дн) | F1: Продвижение: Выбирают чаще (5 дн) | G1: Продвижение: Сильнее (5 дн) | H1: Выделение цветом (7 дн) | I1: XL (7 дн) | J1: Обновлено
A2: Москва | B2: 641 | C2: 856 | D2: 1540 | E2: 1660 | F2: 3215 | G2: 6505 | H2: 373 | I2: 373 | J2: 2026-06-16
A3: Санкт-Петербург | B3: 1435 | C3: 1915 | D3: 3446 | E3: 1460 | F3: 2850 | G3: 5765 | H3: 329 | I3: 329 | J3: 2026-06-16
A4: Новосибирск | B4: 1378 | C4: 1836 | D4: 3305 | E4: 1255 | F4: 2465 | G4: 4940 | H4: 285 | I4: 285 | J4: 2026-06-16
A5: Екатеринбург | B5: 1282 | C5: 1708 | D5: 3073 | E5: 1255 | F5: 2465 | G5: 4940 | H5: 285 | I5: 285 | J5: 2026-06-16
A6: Казань | B6: 1625 | C6: 2167 | D6: 3900 | E6: 1515 | F6: 3060 | G6: 6175 | H6: 351 | I6: 351 | J6: 2026-06-16
A7: Красноярск | B7: 1949 | C7: 2600 | D7: 4677 | E7: 965 | F7: 1915 | G7: 3865 | H7: 219 | I7: 219 | J7: 2026-06-16
A8: Нижний Новгород | B8: 1249 | C8: 1666 | D8: 3001 | E8: 1165 | F8: 2280 | G8: 4610 | H8: 263 | I8: 263 | J8: 2026-06-16
A9: Челябинск | B9: 1810 | C9: 2410 | D9: 4340 | E9: 1255 | F9: 2465 | G9: 4940 | H9: 285 | I9: 285 | J9: 2026-06-16
A10: Уфа | B10: 1361 | C10: 1814 | D10: 3268 | E10: 1515 | F10: 3060 | G10: 6175 | H10: 351 | I10: 351 | J10: 2026-06-16
A11: Краснодар | B11: 2105 | C11: 2806 | D11: 5053 | E11: 1605 | F11: 3140 | G11: 6340 | H11: 362 | I11: 362 | J11: 2026-06-16
A12: Самара | B12: 1319 | C12: 1757 | D12: 3163 | E12: 1165 | F12: 2280 | G12: 4610 | H12: 351 | I12: 351 | J12: 2026-06-16
A13: Ростов-на-Дону | B13: 1607 | C13: 2144 | D13: 3859 | E13: 1220 | F13: 2355 | G13: 4775 | H13: 274 | I13: 274 | J13: 2026-06-16
... A17: Волгоград | B17: 1419 | C17: 1891 | D17: 3406 | E17: 1365 | F17: 2645 | G17: 5350 | H17: 307 | I17: 307 | J17: 2026-06-16

Sheet Динамика цен
A1: Источник | B1: Город | C1: Категория | D1: Тип цены | E1: июн.2026 | F1: Δ%
A2: Avito | B2: Москва | D2: Публикация 14 дн | E2: 641
A3: Avito | B3: Москва | D3: Публикация 30 дн | E3: 856
A4: Avito | B4: Москва | D4: Публикация 60 дн | E4: 1540
A5: Avito | B5: Москва | D5: Продвижение: Оценить (5 дн) | E5: 1660
A6: Avito | B6: Москва | D6: Продвижение: Выбирают чаще (5 дн) | E6: 3215
A7: Avito | B7: Москва | D7: Продвижение: Сильнее (5 дн) | E7: 6505
A8: Avito | B8: Москва | D8: Выделение цветом (7 дн) | E8: 373
A9: Avito | B9: Москва | D9: XL (7 дн) | E9: 373
A10: Avito | B10: Санкт-Петербург | D10: Публикация 14 дн | E10: 1435
A11: Avito | B11: Санкт-Петербург | D11: Публикация 30 дн | E11: 1915
A12: Avito | B12: Санкт-Петербург | D12: Публикация 60 дн | E12: 3446
A13: Avito | B13: Санкт-Петербург | D13: Продвижение: Оценить (5 дн) | E13: 1460
... A129: Avito | B129: Волгоград | D129: XL (7 дн) | E129: 307
A130: CIAN | B130: Москва | C130: Продажа · Городская · Квартира | D130: Публикация, ₽/30 дн | E130: 3390
A131: CIAN | B131: Москва | C131: Продажа · Городская · Квартира | D131: Топ, ₽/сут | E131: 1213
A132: CIAN | B132: Москва | C132: Продажа · Городская · Квартира | D132: Премиум, ₽/сут | E132: 492
A133: CIAN | B133: Москва | C133: Продажа · Городская · Квартира | D133: Стандарт, ₽/сут | E133: 162
A134: CIAN | B134: Санкт-Петербург | C134: Продажа · Городская · Квартира | D134: Публикация, ₽/30 дн | E134: 1560
A135: CIAN | B135: Санкт-Петербург | C135: Продажа · Городская · Квартира | D135: Топ, ₽/сут | E135: 598
A136: CIAN | B136: Санкт-Петербург | C136: Продажа · Городская · Квартира | D136: Премиум, ₽/сут | E136: 255
A137: CIAN | B137: Санкт-Петербург | C137: Продажа · Городская · Квартира | D137: Стандарт, ₽/сут | E137: 108
A138: CIAN | B138: Новосибирск | C138: Продажа · Городская · Квартира | D138: Публикация, ₽/30 дн | E138: 1596
A139: CIAN | B139: Новосибирск | C139: Продажа · Городская · Квартира | D139: Топ, ₽/сут | E139: 420
A140: CIAN | B140: Новосибирск | C140: Продажа · Городская · Квартира | D140: Премиум, ₽/сут | E140: 189
A141: CIAN | B141: Новосибирск | C141: Продажа · Городская · Квартира | D141: Стандарт, ₽/сут | E141: 56
... A150: CIAN | B150: Красноярск | C150: Продажа · Городская · Квартира | D150: Публикация, ₽/30 дн | E150: 573
A151: CIAN | B151: Красноярск | C151: Продажа · Городская · Квартира | D151: Топ, ₽/сут | E151: —
A152: CIAN | B152: Красноярск | C152: Продажа · Городская · Квартира | D152: Премиум, ₽/сут | E152: —
A153: CIAN | B153: Красноярск | C153: Продажа · Городская · Квартира | D153: Стандарт, ₽/сут | E153: —
A154: CIAN | B154: Нижний Новгород | C154: Продажа · Городская · Квартира | D154: Публикация, ₽/30 дн | E154: 441
A155: CIAN | B155: Нижний Новгород | C155: Продажа · Городская · Квартира | D155: Топ, ₽/сут | E155: 208
A156: CIAN | B156: Нижний Новгород | C156: Продажа · Городская · Квартира | D156: Премиум, ₽/сут | E156: 81
A157: CIAN | B157: Нижний Новгород | C157: Продажа · Городская · Квартира | D157: Стандарт, ₽/сут | E157: 23
A158: CIAN | B158: Челябинск | C158: Продажа · Городская · Квартира | D158: Публикация, ₽/30 дн | E158: 291
A159: CIAN | B159: Челябинск | C159: Продажа · Городская · Квартира | D159: Топ, ₽/сут | E159: 203
A160: CIAN | B160: Челябинск | C160: Продажа · Городская · Квартира | D160: Премиум, ₽/сут | E160: 95
A161: CIAN | B161: Челябинск | C161: Продажа · Городская · Квартира | D161: Стандарт, ₽/сут | E161: 27
A162: CIAN | B162: Уфа | C162: Продажа · Городская · Квартира | D162: Публикация, ₽/30 дн | E162: 213
A163: CIAN | B163: Уфа | C163: Продажа · Городская · Квартира | D163: Топ, ₽/сут | E163: 176
...
